Workbook
Name AccountStatus: #REF!
Name BANKING_DATABASE_FINAL: #REF!
Name Beta: #REF!
Name Branch1: #REF!
Name Constant.No.Factor: [1]Score!$D$119
Name Country: OFFSET([2]Master!$B$3,1,0,COUNTA([2]Master!$B:$B)-1)
Name CrfFileName: [3]ws!$B$28
Name DataMonthName: [3]ws!$B$3
Name DataYear: [3]ws!$B$18
Name Excel_BuiltIn_Print_Area_10: #REF!
Name Excel_BuiltIn_Print_Area_10_1: NA()
Name Exclusion_Flag: OFFSET('[4]Score Generator'!$CK$8,0,0,COUNTA(INDIRECT("'Score Generator'!$A$5:$A"&ROWS('[4]Score Generator'!$A:$A))),1)
Name External_Credit_Rating: OFFSET('[5]Score Generator'!$BJ$8,0,0,COUNTA(INDIRECT("'Score Generator'!$A$5:$A"&ROWS('[5]Score Generator'!$A:$A))),1)
Name Issue_Priority: #REF!
Name Issue_Status: #REF!
Name Issue_Workstream: #REF!
Name NameThai: [3]ws!$H$5
Name PositionName: [3]ws!$H$6
Name PrintBy: [3]ws!$H$4
Name PrintDate: [3]ws!$H$3
Name Ref_No: OFFSET('[4]Score Generator'!$A$8,0,0,COUNTA(INDIRECT("'Score Generator'!$A$5:$A"&ROWS('[4]Score Generator'!$A:$A))),1)
Name ReqStatus: [6]Sheet1!$A$31:$A$33
Name Risk_Impact: #REF!
Name Risk_Probability: #REF!
Name Risk_Status: #REF!
Name Risk_Workstream: #REF!
Name Score_Gen_Value: OFFSET('[4]Score Generator'!$A$8,0,0,COUNTA(INDIRECT("'Score Generator'!$A$5:$A"&ROWS('[4]Score Generator'!$A:$A))),COUNTA('[4]Score Generator'!$A$5:$DF$5))
Name sfs: #REF!
Name Status: #REF!
Name u: #REF!
Name unrated: #REF!

Sheet Instructions
B2: Background and Problem Statement
B3: • This exercise is related to credit scoring or scorecard development. The loans portfolio in scope is SME portfolio of the Bank. • Due to fairly low defaulted cases (50 cases), the Credit Scorecard development would adopt the Hybrid approach (between Expert-based and Statistical analysis). • The weights of each feature and risk component of the scorecard are currently determined based on the Bank's credit experts judgement. • However, the Bank would like to employ data or quantiatative analysis to objectively support the determination of such weights.
B5: Input Data Provided:
B6: • This spreadsheet contains the input data for credit scorecard development.
B7: Notes for Input Data - Only eight generic features related to customers’ credit history and financial factors are provided for this exercise. - The Default Flag is provided (i.e. whether a customer has ever exceeded 90 days past due (DPD) within the next 24 months), where a value of 1 denotes default. - The sheet 'Data' contains data before applying binning or grouping. - The sheet 'Data_Bin' contains data after applying binning or grouping to numerical features. - Some numerical features contain specially assigned values (e.g., 99999999, 99999998) to indicate special cases or invalid calculations (such as when the denominator equals zero). - The sheet 'Scorecard' provides the assigned credit scores corresponding to each attribute..
B9: Instruction:
B10: • Please provide your answers in sheet 'Test'. The focus is to use data and quantitative analysis to justify and support your rationales or point of views. • You can use Python or MS Excel to perform the data and quantitative analysis. • You are required to prepare up to a total of 12 slides covering the following areas, the presentation slides you draft will be used as part of the interview evaluation process. • Please revert this file (and any necessary working files) and present your work in the session. You will have 20 minutes for the presentation.

Sheet Data
A1: Cus_ID | B1: Debt restructuring history | C1: Debt rescheduling history (reschedule) | D1: Worst credit bureau delinquency record in the past 2 years | E1: Net Fixed Asset | F1: Net Profit Margin (%) | G1: Sale Growth (%) | H1: Debt-to-Equity Ratio | I1: Debt Service Coverage Area | J1: Default Flag
A2: 1 | B2: No debt restructuring history | C2: No debt rescheduling history (payment term relief) | D2: Record found in credit bureau but no delinquency history | E2: 38169496 | F2: -113.26 | G2: -56.14 | H2: 99999998 | I2: -0.41179 | J2: 0
A3: 2 | B3: No debt restructuring history | C3: No debt rescheduling history (payment term relief) | D3: Record found in credit bureau but no delinquency history | E3: 16781677 | F3: -54.94 | G3: -6.99 | H3: 99999998 | I3: -0.31211 | J3: 0
A4: 3 | B4: No debt restructuring history | C4: No debt rescheduling history (payment term relief) | D4: Record found in credit bureau but no delinquency history | E4: 213151797 | F4: -84.12286 | G4: -46.76026 | H4: 0.53141 | I4: 0.0856 | J4: 0
A5: 4 | B5: No debt restructuring history | C5: No debt rescheduling history (payment term relief) | D5: Record found in credit bureau but no delinquency history | E5: 1181179164 | F5: -80.71586 | G5: -33.07817 | H5: 0.47271 | I5: 0.09958 | J5: 0
A6: 5 | B6: Restructured debt with regular payments for more than 12 months | C6: Rescheduled debt with regular payments for more than 12 months | D6: Record found in credit bureau but no delinquency history | E6: 3.7597975e+08 | F6: -285.6987 | G6: -84.03822 | H6: 99999998 | I6: 0.63897 | J6: 0
A7: 6 | B7: No debt restructuring history | C7: No debt rescheduling history (payment term relief) | D7: Record found in credit bureau but no delinquency history | E7: 72606642 | F7: -176.74375 | G7: -86.47437 | H7: 99999998 | I7: -1.09041 | J7: 0
A8: 7 | B8: Restructured debt with regular payments for 6-12 months | C8: Rescheduled debt with regular payments for 6-12 months | D8: Overdue more than 90 days within the past 1 year | E8: 3.0160438e+08 | F8: -92.85954 | G8: 55.35001 | H8: 0.7464 | I8: -0.81684 | J8: 0
A9: 8 | B9: No debt restructuring history | C9: Rescheduled debt with regular payments for 6-12 months | D9: Record found in credit bureau but no delinquency history | E9: 1.5420959e+09 | F9: 10.19 | G9: 30.86 | H9: 1.26157 | I9: 0.83338 | J9: 0
A10: 9 | B10: No debt restructuring history | C10: Rescheduled debt with regular payments for more than 12 months | D10: Record found in credit bureau but no delinquency history | E10: 27203707 | F10: -17.70526 | G10: -41.47401 | H10: 99999998 | I10: 0.23822 | J10: 0
A11: 10 | B11: No debt restructuring history | C11: No debt rescheduling history (payment term relief) | D11: Record found in credit bureau but no delinquency history | E11: 7086263.8 | F11: -92.61 | G11: -29.64 | H11: 1.11335 | I11: -0.02576 | J11: 0
A12: 11 | B12: No debt restructuring history | C12: No debt rescheduling history (payment term relief) | D12: Record found in credit bureau but no delinquency history | E12: 23169182 | F12: -205.41897 | G12: -69.58607 | H12: 99999998 | I12: -0.14431 | J12: 0
A13: 12 | B13: No debt restructuring history | C13: No debt rescheduling history (payment term relief) | D13: Record found in credit bureau but no delinquency history | E13: 1.3505688e+09 | F13: 13.064 | G13: -13.18579 | H13: 0.38582 | I13: 1.84288 | J13: 0
... A15: 14 | B15: No debt restructuring history | C15: Rescheduled debt with regular payments for less than 6 months | D15: Record found in credit bureau but no delinquency history | E15: 1.8146398e+08 | F15: -211.17703 | G15: -82.18576 | H15: -2.14765 | I15: -0.04452 | J15: 0
A16: 15 | B16: No debt restructuring history | C16: No debt rescheduling history (payment term relief) | D16: Record found in credit bureau but no delinquency history | E16: 1.8059602e+08 | F16: 1.97 | G16: -80.94 | H16: 0.51579 | J16: 0
A17: 16 | B17: No debt restructuring history | C17: Rescheduled debt with regular payments for less than 6 months | D17: Record found in credit bureau but no delinquency history | E17: 2.1792275e+08 | F17: -182.22162 | G17: -76.01723 | H17: 99999998 | I17: -0.28953 | J17: 0
A18: 17 | B18: No debt restructuring history | C18: Rescheduled debt with regular payments for more than 12 months | D18: Overdue 1-30 days within the past 1 year | E18: 83578129 | F18: -641.15591 | G18: -91.21621 | H18: 99999998 | I18: -0.29518 | J18: 0
A19: 18 | B19: No debt restructuring history | C19: No debt rescheduling history (payment term relief) | D19: Record found in credit bureau but no delinquency history | E19: 1.8076858e+08 | F19: -83.90369 | G19: 3.30007 | H19: 0.52191 | I19: -1.37526 | J19: 0
A20: 19 | B20: No debt restructuring history | C20: No debt rescheduling history (payment term relief) | D20: Record found in credit bureau but no delinquency history | E20: 1898769.7 | F20: -324.23 | G20: -55.21 | H20: 99999998 | I20: -0.00361 | J20: 0
A21: 20 | B21: No debt restructuring history | C21: No debt rescheduling history (payment term relief) | D21: Record found in credit bureau but no delinquency history | E21: 20436236 | F21: -127.93552 | G21: -77.07892 | H21: 99999998 | I21: -0.10384 | J21: 0
A22: 21 | B22: No debt restructuring history | C22: No debt rescheduling history (payment term relief) | D22: Record found in credit bureau but no delinquency history | E22: 28518995 | F22: -153.42 | G22: -41.02 | H22: 99999998 | I22: -0.17237 | J22: 0
A23: 22 | B23: No debt restructuring history | C23: No debt rescheduling history (payment term relief) | D23: Credit bureau check not performed (exempted) | E23: 9687738251 | F23: -128.02879 | G23: -66.37212 | H23: 2.43967 | I23: -0.37221 | J23: 0
A24: 23 | B24: No debt restructuring history | C24: › | D24: Record found in credit bureau but no delinquency history | E24: 3251922517 | F24: -3.31578 | G24: -9.62089 | H24: 0.75828 | I24: 0.94204 | J24: 0
A25: 24 | B25: No debt restructuring history | C25: No debt rescheduling history (payment term relief) | D25: Record found in credit bureau but no delinquency history | E25: 1.2945699e+08 | F25: -19.84688 | G25: -55.53527 | H25: 1.37861 | I25: 0.35044 | J25: 0
A26: 25 | B26: No debt restructuring history | C26: No debt rescheduling history (payment term relief) | D26: Credit bureau check not performed | E26: 68621430 | F26: -54.57 | G26: -30.81 | H26: 99999998 | I26: 1.94255 | J26: 0
A27: 26 | B27: No debt restructuring history | C27: No debt rescheduling history (payment term relief) | D27: Record found in credit bureau but no delinquency history | E27: 33257577 | F27: -36.72 | G27: 86.85 | H27: 2.00054 | I27: 2.35213 | J27: 0
A28: 27 | B28: No debt restructuring history | C28: No debt rescheduling history (payment term relief) | D28: Record found in credit bureau but no delinquency history | E28: 2.5183254e+08 | F28: -274.57551 | G28: -86.51197 | H28: 99999998 | I28: -0.56665 | J28: 0
... A36: 35 | B36: Restructured debt with regular payments for 6-12 months | C36: Rescheduled debt with regular payments for 6-12 months | D36: Overdue more than 90 days within the past 1 year | E36: 60588794 | F36: -347.81089 | G36: -0.26914 | H36: 99999998 | I36: -0.98191 | J36: 0
A37: 36 | B37: Restructured debt with regular payments for less than 6 months | C37: Rescheduled debt with regular payments for 6-12 months | D37: Overdue more than 90 days within the past 1 year | E37: 56114.95 | F37: 42.12968 | G37: -29.20168 | H37: 0.01669 | J37: 1
A38: 37 | B38: No debt restructuring history | C38: No debt rescheduling history (payment term relief) | D38: Record found in credit bureau but no delinquency history | E38: 1.9535134e+08 | F38: -10.51651 | G38: -3.47424 | H38: -2.76748 | I38: 0.66035 | J38: 0
A39: 38 | B39: No debt restructuring history | C39: No debt rescheduling history (payment term relief) | D39: Record found in credit bureau but no delinquency history | E39: 2.348659e+08 | F39: -2.86 | G39: -5.36 | H39: -3.61112 | I39: 0.79104 | J39: 0
A40: 39 | B40: No debt restructuring history | C40: No debt rescheduling history (payment term relief) | D40: Record found in credit bureau but no delinquency history | E40: 69932010 | F40: 6.98248 | G40: -70.25848 | H40: 2.11822 | I40: 1.19782 | J40: 0
A41: 40 | B41: No debt restructuring history | C41: No debt rescheduling history (payment term relief) | D41: Credit bureau check not performed (exempted) | E41: 2532176365 | F41: -27.21663 | G41: -37.64652 | H41: 15.21586 | I41: -7.93745 | J41: 0
A42: 41 | B42: Restructured debt with regular payments for less than 6 months | C42: Rescheduled debt with regular payments for 6-12 months | D42: Overdue more than 90 days within the past 1 year | E42: 56114.95 | F42: 42.12968 | G42: -29.20168 | H42: 99999999 | J42: 1
A43: 42 | B43: No debt restructuring history | C43: No debt rescheduling history (payment term relief) | D43: Record found in credit bureau but no delinquency history | E43: 75005392 | F43: -24.65699 | G43: -10.73973 | H43: 0.63251 | I43: 2.35407 | J43: 0
A44: 43 | B44: Restructured debt with regular payments for more than 12 months | C44: Rescheduled debt with regular payments for more than 12 months | D44: Record found in credit bureau but no delinquency history | E44: 4.0310022e+08 | F44: 33.73 | G44: -4.76 | H44: 99999998 | I44: 1.79804 | J44: 0
A45: 44 | B45: No debt restructuring history | C45: No debt rescheduling history (payment term relief) | D45: Record found in credit bureau but no delinquency history | E45: 53753485 | F45: 1.08 | G45: -4.13 | H45: 0.54547 | I45: 0.79049 | J45: 0
A46: 45 | B46: No debt restructuring history | C46: Rescheduled debt with regular payments for more than 12 months | D46: Record found in credit bureau but no delinquency history | E46: 23803228 | F46: -0.65055 | G46: -3.12187 | H46: 99999999 | I46: 0.62879 | J46: 0
A47: 46 | B47: No debt restructuring history | C47: Rescheduled debt with regular payments for more than 12 months | D47: Record found in credit bureau but no delinquency history | E47: 144304127 | F47: 1.59016 | G47: -11.11203 | H47: -8.58703 | I47: 0.80596 | J47: 0
A48: 47 | B48: No debt restructuring history | C48: Rescheduled debt with regular payments for 6-12 months | D48: Overdue 61–90 days within the past 1 year | E48: 1.6052255e+09 | F48: -73.62 | G48: 18.3 | H48: 1.34697 | I48: 0.18769 | J48: 0
...

Sheet Data_Bin
A1: Cus_ID | B1: Debt restructuring history | C1: Debt rescheduling history (reschedule) | D1: Worst credit bureau delinquency record in the past 2 years | E1: Net Fixed Asset | F1: Net Profit Margin (%) | G1: Sale Growth (%) | H1: Debt-to-Equity Ratio | I1: Debt Service Coverage Area | J1: Default Flag
A2: 1 | B2: No debt restructuring history | C2: No debt rescheduling history (payment term relief) | D2: Record found in credit bureau but no delinquency history | E2: (0, 50000000) | F2: <=0 | G2: <=0 | H2: 99999998 | I2: <=0 | J2: 0
A3: 2 | B3: No debt restructuring history | C3: No debt rescheduling history (payment term relief) | D3: Record found in credit bureau but no delinquency history | E3: (0, 50000000) | F3: <=0 | G3: <=0 | H3: 99999998 | I3: <=0 | J3: 0
A4: 3 | B4: No debt restructuring history | C4: No debt rescheduling history (payment term relief) | D4: Record found in credit bureau but no delinquency history | E4: (150000000, 250000000) | F4: <=0 | G4: <=0 | H4: (0.5, 1) | I4: (0, 0.25) | J4: 0
A5: 4 | B5: No debt restructuring history | C5: No debt rescheduling history (payment term relief) | D5: Record found in credit bureau but no delinquency history | E5: >250000000 | F5: <=0 | G5: <=0 | H5: (0, 0.5) | I5: (0, 0.25) | J5: 0
A6: 5 | B6: Restructured debt with regular payments for more than 12 months | C6: Rescheduled debt with regular payments for more than 12 months | D6: Record found in credit bureau but no delinquency history | E6: >250000000 | F6: <=0 | G6: <=0 | H6: 99999998 | I6: (0.5, 0.75) | J6: 0
A7: 6 | B7: No debt restructuring history | C7: No debt rescheduling history (payment term relief) | D7: Record found in credit bureau but no delinquency history | E7: (50000000, 100000000) | F7: <=0 | G7: <=0 | H7: 99999998 | I7: <=0 | J7: 0
A8: 7 | B8: Restructured debt with regular payments for 6-12 months | C8: Rescheduled debt with regular payments for 6-12 months | D8: Overdue more than 90 days within the past 1 year | E8: >250000000 | F8: <=0 | G8: >30 | H8: (0.5, 1) | I8: <=0 | J8: 0
A9: 8 | B9: No debt restructuring history | C9: Rescheduled debt with regular payments for 6-12 months | D9: Record found in credit bureau but no delinquency history | E9: >250000000 | F9: (7.5, 15) | G9: >30 | H9: (1, 1.5) | I9: (0.75, 1) | J9: 0
A10: 9 | B10: No debt restructuring history | C10: Rescheduled debt with regular payments for more than 12 months | D10: Record found in credit bureau but no delinquency history | E10: (0, 50000000) | F10: <=0 | G10: <=0 | H10: 99999998 | I10: (0, 0.25) | J10: 0
A11: 10 | B11: No debt restructuring history | C11: No debt rescheduling history (payment term relief) | D11: Record found in credit bureau but no delinquency history | E11: (0, 50000000) | F11: <=0 | G11: <=0 | H11: (1, 1.5) | I11: <=0 | J11: 0
A12: 11 | B12: No debt restructuring history | C12: No debt rescheduling history (payment term relief) | D12: Record found in credit bureau but no delinquency history | E12: (0, 50000000) | F12: <=0 | G12: <=0 | H12: 99999998 | I12: <=0 | J12: 0
A13: 12 | B13: No debt restructuring history | C13: No debt rescheduling history (payment term relief) | D13: Record found in credit bureau but no delinquency history | E13: >250000000 | F13: (7.5, 15) | G13: <=0 | H13: (0, 0.5) | I13: (1.2, 2) | J13: 0
A14: 13 | B14: No debt restructuring history | C14: Rescheduled debt with regular payments for less than 6 months | D14: Record found in credit bureau but no delinquency history | E14: (50000000, 100000000) | F14: <=0 | G14: <=0 | H14: (0.5, 1) | I14: (0.25, 0.5) | J14: 0
A15: 14 | B15: No debt restructuring history | C15: Rescheduled debt with regular payments for less than 6 months | D15: Record found in credit bureau but no delinquency history | E15: (150000000, 250000000) | F15: <=0 | G15: <=0 | H15: <=0 | I15: <=0 | J15: 0
A16: 15 | B16: No debt restructuring history | C16: No debt rescheduling history (payment term relief) | D16: Record found in credit bureau but no delinquency history | E16: (150000000, 250000000) | F16: (0, 2.5) | G16: <=0 | H16: (0.5, 1) | J16: 0
A17: 16 | B17: No debt restructuring history | C17: Rescheduled debt with regular payments for less than 6 months | D17: Record found in credit bureau but no delinquency history | E17: (150000000, 250000000) | F17: <=0 | G17: <=0 | H17: 99999998 | I17: <=0 | J17: 0
A18: 17 | B18: No debt restructuring history | C18: Rescheduled debt with regular payments for more than 12 months | D18: Overdue 1-30 days within the past 1 year | E18: (50000000, 100000000) | F18: <=0 | G18: <=0 | H18: 99999998 | I18: <=0 | J18: 0
A19: 18 | B19: No debt restructuring history | C19: No debt rescheduling history (payment term relief) | D19: Record found in credit bureau but no delinquency history | E19: (150000000, 250000000) | F19: <=0 | G19: (0, 5) | H19: (0.5, 1) | I19: <=0 | J19: 0
A20: 19 | B20: No debt restructuring history | C20: No debt rescheduling history (payment term relief) | D20: Record found in credit bureau but no delinquency history | E20: (0, 50000000) | F20: <=0 | G20: <=0 | H20: 99999998 | I20: <=0 | J20: 0
A21: 20 | B21: No debt restructuring history | C21: No debt rescheduling history (payment term relief) | D21: Record found in credit bureau but no delinquency history | E21: (0, 50000000) | F21: <=0 | G21: <=0 | H21: 99999998 | I21: <=0 | J21: 0
A22: 21 | B22: No debt restructuring history | C22: No debt rescheduling history (payment term relief) | D22: Record found in credit bureau but no delinquency history | E22: (0, 50000000) | F22: <=0 | G22: <=0 | H22: 99999998 | I22: <=0 | J22: 0
A23: 22 | B23: No debt restructuring history | C23: No debt rescheduling history (payment term relief) | D23: Credit bureau check not performed (exempted) | E23: >250000000 | F23: <=0 | G23: <=0 | H23: (1.5, 3) | I23: <=0 | J23: 0
A24: 23 | B24: No debt restructuring history | C24: No debt rescheduling history (payment term relief) | D24: Record found in credit bureau but no delinquency history | E24: >250000000 | F24: <=0 | G24: <=0 | H24: (0.5, 1) | I24: (0.75, 1) | J24: 0
A25: 24 | B25: No debt restructuring history | C25: No debt rescheduling history (payment term relief) | D25: Record found in credit bureau but no delinquency history | E25: (100000000, 150000000) | F25: <=0 | G25: <=0 | H25: (1, 1.5) | I25: (0.25, 0.5) | J25: 0
A26: 25 | B26: No debt restructuring history | C26: No debt rescheduling history (payment term relief) | D26: Credit bureau check not performed | E26: (50000000, 100000000) | F26: <=0 | G26: <=0 | H26: 99999998 | I26: (1.2, 2) | J26: 0
A27: 26 | B27: No debt restructuring history | C27: No debt rescheduling history (payment term relief) | D27: Record found in credit bureau but no delinquency history | E27: (0, 50000000) | F27: <=0 | G27: >30 | H27: (1.5, 3) | I27: >2 | J27: 0
A28: 27 | B28: No debt restructuring history | C28: No debt rescheduling history (payment term relief) | D28: Record found in credit bureau but no delinquency history | E28: >250000000 | F28: <=0 | G28: <=0 | H28: 99999998 | I28: <=0 | J28: 0
A29: 28 | B29: No debt restructuring history | C29: No debt rescheduling history (payment term relief) | D29: Overdue more than 90 days within the past 1 year | E29: (50000000, 100000000) | F29: 99999999 | G29: <=0 | H29: (1.5, 3) | I29: <=0 | J29: 0
A30: 29 | B30: No debt restructuring history | C30: No debt rescheduling history (payment term relief) | D30: Record found in credit bureau but no delinquency history | E30: >250000000 | F30: <=0 | G30: <=0 | H30: (0, 0.5) | I30: (0.5, 0.75) | J30: 0
A31: 30 | B31: No debt restructuring history | C31: Rescheduled debt with regular payments for less than 6 months | D31: Record found in credit bureau but no delinquency history | E31: (100000000, 150000000) | F31: 99999999 | G31: 99999999 | H31: (1, 1.5) | I31: <=0 | J31: 0
A32: 31 | B32: No debt restructuring history | C32: Rescheduled debt with regular payments for less than 6 months | D32: Overdue 1-30 days within the past 1 year | E32: >250000000 | F32: >15 | G32: <=0 | H32: (1.5, 3) | I32: (1.2, 2) | J32: 0
A33: 32 | B33: No debt restructuring history | C33: No debt rescheduling history (payment term relief) | D33: Credit bureau check not performed (exempted) | E33: >250000000 | F33: <=0 | G33: <=0 | H33: (1.5, 3) | I33: <=0 | J33: 0
A34: 33 | B34: No debt restructuring history | C34: Rescheduled debt with regular payments for more than 12 months | D34: Record found in credit bureau but no delinquency history | E34: (100000000, 150000000) | F34: (0, 2.5) | G34: <=0 | H34: <=0 | I34: (0.75, 1) | J34: 0
A35: 34 | B35: No debt restructuring history | C35: No debt rescheduling history (payment term relief) | D35: Overdue 31–60 days within the past 1 year | E35: (50000000, 100000000) | F35: (2.5, 7.5) | G35: <=0 | H35: (1.5, 3) | I35: (1, 1.2) | J35: 0
A36: 35 | B36: Restructured debt with regular payments for 6-12 months | C36: Rescheduled debt with regular payments for 6-12 months | D36: Overdue more than 90 days within the past 1 year | E36: (50000000, 100000000) | F36: <=0 | G36: <=0 | H36: 99999998 | I36: <=0 | J36: 0
A37: 36 | B37: Restructured debt with regular payments for less than 6 months | C37: Rescheduled debt with regular payments for 6-12 months | D37: Overdue more than 90 days within the past 1 year | E37: (0, 50000000) | F37: >15 | G37: <=0 | H37: (0, 0.5) | J37: 1
A38: 37 | B38: No debt restructuring history | C38: No debt rescheduling history (payment term relief) | D38: Record found in credit bureau but no delinquency history | E38: (150000000, 250000000) | F38: <=0 | G38: <=0 | H38: <=0 | I38: (0.5, 0.75) | J38: 0
A39: 38 | B39: No debt restructuring history | C39: No debt rescheduling history (payment term relief) | D39: Record found in credit bureau but no delinquency history | E39: (150000000, 250000000) | F39: <=0 | G39: <=0 | H39: <=0 | I39: (0.75, 1) | J39: 0
A40: 39 | B40: No debt restructuring history | C40: No debt rescheduling history (payment term relief) | D40: Record found in credit bureau but no delinquency history | E40: (50000000, 100000000) | F40: (2.5, 7.5) | G40: <=0 | H40: (1.5, 3) | I40: (1, 1.2) | J40: 0
...

Sheet Data_Bin_clean
A1: Cus_ID | B1: Debt restructuring history | C1: Debt rescheduling history (reschedule) | D1: Worst credit bureau delinquency record in the past 2 years | E1: Net Fixed Asset | F1: Net Profit Margin (%) | G1: Sale Growth (%) | H1: Debt-to-Equity Ratio | I1: Debt Service Coverage Area | J1: Default Flag
A2: 1 | B2: No debt restructuring history | C2: No debt rescheduling history (payment term relief) | D2: Record found in credit bureau but no delinquency history | E2: (0, 50000000) | F2: <=0 | G2: <=0 | H2: Not available | I2: <=0 | J2: 0
A3: 2 | B3: No debt restructuring history | C3: No debt rescheduling history (payment term relief) | D3: Record found in credit bureau but no delinquency history | E3: (0, 50000000) | F3: <=0 | G3: <=0 | H3: Not available | I3: <=0 | J3: 0
A4: 3 | B4: No debt restructuring history | C4: No debt rescheduling history (payment term relief) | D4: Record found in credit bureau but no delinquency history | E4: (150000000, 250000000) | F4: <=0 | G4: <=0 | H4: (0.5, 1) | I4: (0, 0.25) | J4: 0
A5: 4 | B5: No debt restructuring history | C5: No debt rescheduling history (payment term relief) | D5: Record found in credit bureau but no delinquency history | E5: >250000000 | F5: <=0 | G5: <=0 | H5: (0, 0.5) | I5: (0, 0.25) | J5: 0
A6: 5 | B6: Restructured debt with regular payments for more than 12 months | C6: Rescheduled debt with regular payments for more than 12 months | D6: Record found in credit bureau but no delinquency history | E6: >250000000 | F6: <=0 | G6: <=0 | H6: Not available | I6: (0.5, 0.75) | J6: 0
A7: 6 | B7: No debt restructuring history | C7: No debt rescheduling history (payment term relief) | D7: Record found in credit bureau but no delinquency history | E7: (50000000, 100000000) | F7: <=0 | G7: <=0 | H7: Not available | I7: <=0 | J7: 0
A8: 7 | B8: Restructured debt with regular payments for 6-12 months | C8: Rescheduled debt with regular payments for 6-12 months | D8: Overdue more than 90 days within the past 1 year | E8: >250000000 | F8: <=0 | G8: >30 | H8: (0.5, 1) | I8: <=0 | J8: 0
A9: 8 | B9: No debt restructuring history | C9: Rescheduled debt with regular payments for 6-12 months | D9: Record found in credit bureau but no delinquency history | E9: >250000000 | F9: (7.5, 15) | G9: >30 | H9: (1, 1.5) | I9: (0.75, 1) | J9: 0
A10: 9 | B10: No debt restructuring history | C10: Rescheduled debt with regular payments for more than 12 months | D10: Record found in credit bureau but no delinquency history | E10: (0, 50000000) | F10: <=0 | G10: <=0 | H10: Not available | I10: (0, 0.25) | J10: 0
A11: 10 | B11: No debt restructuring history | C11: No debt rescheduling history (payment term relief) | D11: Record found in credit bureau but no delinquency history | E11: (0, 50000000) | F11: <=0 | G11: <=0 | H11: (1, 1.5) | I11: <=0 | J11: 0
A12: 11 | B12: No debt restructuring history | C12: No debt rescheduling history (payment term relief) | D12: Record found in credit bureau but no delinquency history | E12: (0, 50000000) | F12: <=0 | G12: <=0 | H12: Not available | I12: <=0 | J12: 0
A13: 12 | B13: No debt restructuring history | C13: No debt rescheduling history (payment term relief) | D13: Record found in credit bureau but no delinquency history | E13: >250000000 | F13: (7.5, 15) | G13: <=0 | H13: (0, 0.5) | I13: (1.2, 2) | J13: 0
... A558: 557 | B558: No debt restructuring history | C558: Rescheduled debt with regular payments for more than 12 months | D558: Record found in credit bureau but no delinquency history | E558: (0, 50000000) | F558: (2.5, 7.5) | G558: <=0 | H558: Not available | I558: (0.25, 0.5) | J558: 0

Sheet Scorecard
A2: Unique key | B2: Index | C2: Feature | E2: Credit Score
A3: =CONCATENATE(C3,D3) -> Debt restructuring historyNever restructured debt | B3: C1 | C3: Debt restructuring history | D3: Never restructured debt | E3: 0
A4: =CONCATENATE(C4,D4) -> Debt restructuring historyNo debt restructuring history | C4: Debt restructuring history | D4: No debt restructuring history | E4: 0
A5: =CONCATENATE(C5,D5) -> Debt restructuring historyRestructured debt in the past | C5: Debt restructuring history | D5: Restructured debt in the past | E5: -50
A6: =CONCATENATE(C6,D6) -> Debt restructuring historyRestructured debt with regular payments for more than 12 months | C6: Debt restructuring history | D6: Restructured debt with regular payments for more than 12 months | E6: -50
A7: =CONCATENATE(C7,D7) -> Debt restructuring historyRestructured debt with regular payments for less than 6 months | C7: Debt restructuring history | D7: Restructured debt with regular payments for less than 6 months | E7: -100
A8: =CONCATENATE(C8,D8) -> Debt restructuring historyRestructured debt with regular payments for 6-12 months | C8: Debt restructuring history | D8: Restructured debt with regular payments for 6-12 months | E8: -100
A9: =CONCATENATE(C9,D9) -> Debt restructuring historyCredit bureau check not performed | C9: Debt restructuring history | D9: Credit bureau check not performed | E9: 0
A10: =CONCATENATE(C10,D10) -> Debt restructuring historyNot available | C10: Debt restructuring history | D10: Not available | E10: 0
A11: =CONCATENATE(C11,D11) -> Debt rescheduling history (reschedule)No debt rescheduling history (payment term relief) | B11: C2 | C11: Debt rescheduling history (reschedule) | D11: No debt rescheduling history (payment term relief) | E11: 0
A12: =CONCATENATE(C12,D12) -> Debt rescheduling history (reschedule)Rescheduled debt with regular payments for more than 12 months | C12: Debt rescheduling history (reschedule) | D12: Rescheduled debt with regular payments for more than 12 months | E12: -50
A13: =CONCATENATE(C13,D13) -> Debt rescheduling history (reschedule)Rescheduled debt with regular payments for less than 6 months | C13: Debt rescheduling history (reschedule) | D13: Rescheduled debt with regular payments for less than 6 months | E13: -100
A14: =CONCATENATE(C14,D14) -> Debt rescheduling history (reschedule)Rescheduled debt with regular payments for 6-12 months | C14: Debt rescheduling history (reschedule) | D14: Rescheduled debt with regular payments for 6-12 months | E14: -100
A15: =CONCATENATE(C15,D15) -> Debt rescheduling history (reschedule)Not available | C15: Debt rescheduling history (reschedule) | D15: Not available | E15: 0
A16: =CONCATENATE(C16,D16) -> Worst credit bureau delinquency record in the past 2 yearsRecord found in credit bureau but no delinquency history | B16: C3 | C16: Worst credit bureau delinquency record in the past 2 years | D16: Record found in credit bureau but no delinquency history | E16: 100
A17: =CONCATENATE(C17,D17) -> Worst credit bureau delinquency record in the past 2 yearsCredit bureau check not performed (exempted) | C17: Worst credit bureau delinquency record in the past 2 years | D17: Credit bureau check not performed (exempted) | E17: 100
A18: =CONCATENATE(C18,D18) -> Worst credit bureau delinquency record in the past 2 yearsNo record found in credit bureau | C18: Worst credit bureau delinquency record in the past 2 years | D18: No record found in credit bureau | E18: 0
A19: =CONCATENATE(C19,D19) -> Worst credit bureau delinquency record in the past 2 yearsOverdue 1–30 days more than 1 year ago | C19: Worst credit bureau delinquency record in the past 2 years | D19: Overdue 1–30 days more than 1 year ago | E19: -25
A20: =CONCATENATE(C20,D20) -> Worst credit bureau delinquency record in the past 2 yearsOverdue 1-30 days within the past 1 year | C20: Worst credit bureau delinquency record in the past 2 years | D20: Overdue 1-30 days within the past 1 year | E20: -25
A21: =CONCATENATE(C21,D21) -> Worst credit bureau delinquency record in the past 2 yearsOverdue 31–60 days more than 1 year ago | C21: Worst credit bureau delinquency record in the past 2 years | D21: Overdue 31–60 days more than 1 year ago | E21: -50
A22: =CONCATENATE(C22,D22) -> Worst credit bureau delinquency record in the past 2 yearsOverdue 31–60 days within the past 1 year | C22: Worst credit bureau delinquency record in the past 2 years | D22: Overdue 31–60 days within the past 1 year | E22: -50
A23: =CONCATENATE(C23,D23) -> Worst credit bureau delinquency record in the past 2 yearsOverdue 61–90 days more than 1 year ago | C23: Worst credit bureau delinquency record in the past 2 years | D23: Overdue 61–90 days more than 1 year ago | E23: -75
A24: =CONCATENATE(C24,D24) -> Worst credit bureau delinquency record in the past 2 yearsOverdue 61–90 days within the past 1 year | C24: Worst credit bureau delinquency record in the past 2 years | D24: Overdue 61–90 days within the past 1 year | E24: -75
A25: =CONCATENATE(C25,D25) -> Worst credit bureau delinquency record in the past 2 yearsOverdue more than 90 days more than 1 year ago | C25: Worst credit bureau delinquency record in the past 2 years | D25: Overdue more than 90 days more than 1 year ago | E25: -100
A26: =CONCATENATE(C26,D26) -> Worst credit bureau delinquency record in the past 2 yearsOverdue more than 90 days within the past 1 year | C26: Worst credit bureau delinquency record in the past 2 years | D26: Overdue more than 90 days within the past 1 year | E26: -100
A27: =CONCATENATE(C27,D27) -> Worst credit bureau delinquency record in the past 2 yearsCredit bureau check not performed | C27: Worst credit bureau delinquency record in the past 2 years | D27: Credit bureau check not performed | E27: -100
A28: =CONCATENATE(C28,D28) -> Worst credit bureau delinquency record in the past 2 yearsNot available | C28: Worst credit bureau delinquency record in the past 2 years | D28: Not available | E28: 0
A29: =CONCATENATE(C29,D29) -> Net Fixed Asset>250000000 | B29: F1 | C29: Net Fixed Asset | D29: >250000000 | E29: 100
A30: =CONCATENATE(C30,D30) -> Net Fixed Asset(150000000, 250000000) | C30: Net Fixed Asset | D30: (150000000, 250000000) | E30: 75
A31: =CONCATENATE(C31,D31) -> Net Fixed Asset(100000000, 150000000) | C31: Net Fixed Asset | D31: (100000000, 150000000) | E31: 50
A32: =CONCATENATE(C32,D32) -> Net Fixed Asset(50000000, 100000000) | C32: Net Fixed Asset | D32: (50000000, 100000000) | E32: 25
A33: =CONCATENATE(C33,D33) -> Net Fixed Asset(0, 50000000) | C33: Net Fixed Asset | D33: (0, 50000000) | E33: 0
A34: =CONCATENATE(C34,D34) -> Net Fixed AssetNot available | C34: Net Fixed Asset | D34: Not available | E34: 0
A35: =CONCATENATE(C35,D35) -> Net Profit Margin (%)>15 | B35: F2 | C35: Net Profit Margin (%) | D35: >15 | E35: 100
A36: =CONCATENATE(C36,D36) -> Net Profit Margin (%)(7.5, 15) | C36: Net Profit Margin (%) | D36: (7.5, 15) | E36: 75
A37: =CONCATENATE(C37,D37) -> Net Profit Margin (%)(2.5, 7.5) | C37: Net Profit Margin (%) | D37: (2.5, 7.5) | E37: 50
A38: =CONCATENATE(C38,D38) -> Net Profit Margin (%)(0, 2.5) | C38: Net Profit Margin (%) | D38: (0, 2.5) | E38: 25
A39: =CONCATENATE(C39,D39) -> Net Profit Margin (%)<=0 | C39: Net Profit Margin (%) | D39: <=0 | E39: -50
A40: =CONCATENATE(C40,D40) -> Net Profit Margin (%)Denominator equal to 0 (99999999) | C40: Net Profit Margin (%) | D40: Denominator equal to 0 (99999999) | E40: 0
A41: =CONCATENATE(C41,D41) -> Net Profit Margin (%)Not available | C41: Net Profit Margin (%) | D41: Not available | E41: 0
...

Sheet Test
B3: Candidate Name:
B6: Please provide your answers below. The focus is to use data / quantitative analysis to justify / support your rationales / point of views.
B8: Current State
B9: The Bank's Credit Experts currently determine the weights of each feature and risk component of the scorecard based on expert judgement as follows:
B11: Risk Component / Feature | D11: Weight
B12: C_Credit History | D12: 0.5
C13: C1_History of Debt Restructuring | E13: 0.25
C14: C2_History of Debt Repayment with Rescheduling and Payment Relaxation | E14: 0.25
C15: C3_Worst Credit Bureau Delinquency Record in the Past 2 Years | E15: 0.5
B16: F_Financial Factor | D16: 0.5
C17: F1_Net Fixed Asset | E17: 0.2
C18: F2_Net Profit Margin (%) | E18: 0.2
C19: F3_Sale Growth (%) | E19: 0.2
C20: F4_Debt-to-Equity Ratio | E20: 0.2
C21: F5_Debt Service Coverage Ratio | E21: 0.2
B22: Note: Weights of C+F = 100%, C1+C2+C3 = 100%, F1+F2+F3+F4+F5 = 100%.
B24: Test Questions
B26: 1. Based on the information and data provided, please assess the assigned weights of each feature or risk component (Columns D & E). From the data and quantitative analysis perspective, which features or risk components are over- or under-weight? Please elaborate your rationales.
B27: Answers:
B31: 2. Any suggestions or enhancements regarding the formulated scorecard (i.e. to make it more sensible in terms of a good credit risk model)?
B32: Answers:
B36: 3. How would you approach EDA for a dataset containing borrower financial details, macroeconomic variables, and default history to identify key predictors of default?
B37: Answers:
B41: 4. Can you explain the steps involved in developing a logistic regression model to estimate the Probability of Default (PD) and describe the assumptions underlying this method?
B42: Answers:
B46: 5. How would you evaluate the performance of a logistic regression model for credit risk, including statistical goodness-of-fit, discriminatory power (e.g., AUC-ROC), and forecasting accuracy?
B47: Answers:
... B52: You are required to prepare up to a total of 12 slides covering the following areas, the presentation slides you draft will be used as part of the interview evaluation process.

Sheet Solution
B2: Question 1
C3: Methodology | D3: Implement Weight of Evidence method to measure the predictie power of independent variable in relation to target variable (default, non-default)
D4: The output is Information Value (IV) and it measures the different between event and non-event distribution
D5: Steps:
D6: (1) Assign each value to a bin. In case of continous variable, mapping its value to concrete bin.
D7: (2) Calculate WoE of each bin
D10: (3) Calculate IV Value by summing the WoE of every bin of that feature
D14: By convention, the meaning of IV values are:
D15: IV | E15: Predictive Power
D16: < 0.02 | E16: No predictive power
D17: 0.02 - 0.1 | E17: Weak
D18: 0.1 - 0.3 | E18: Moderate
D19: 0.3-0.5 | E19: Strong
D20: >= 0.5 | E20: Very strong
C22: Example | D22: Here is a IV detail calculation of Debt restructuring history
D24: No debt restructuring history | E24: Total | F24: Event | G24: Dist. Event | H24: Non Event | I24: Dist. Non Event | J24: WoE | K24: IV
D25: No debt restructuring history | E25: =COUNTIF(Data_Bin!$B:$B,D25) -> 233 | F25: =SUMIFS(Data_Bin!J:J,Data_Bin!B:B,D25) -> 12 | G25: =F25/SUM($F$25:$F$31) -> 0.24 | H25: =E25-F25 -> 221 | I25: =H25/SUM($H$25:$H$31) -> 0.43589744 | J25: =LN((G25+0.0000000001)/(I25+0.0000000001)) -> -0.59676805 | K25: =IFERROR(J25*(G25-I25),0) -> 0.11690533
D26: Restructured debt with regular payments for more than 12 months | E26: =COUNTIF(Data_Bin!$B:$B,D26) -> 16 | F26: =SUMIFS(Data_Bin!J:J,Data_Bin!B:B,D26) -> 4 | G26: =F26/SUM($F$25:$F$31) -> 0.08 | H26: =E26-F26 -> 12 | I26: =H26/SUM($H$25:$H$31) -> 0.023668639 | J26: =LN((G26+0.0000000001)/(I26+0.0000000001)) -> 1.2178757 | K26: =IFERROR(J26*(G26-I26),0) -> 0.068604596
D27: Restructured debt with regular payments for 6-12 months | E27: =COUNTIF(Data_Bin!$B:$B,D27) -> 18 | F27: =SUMIFS(Data_Bin!J:J,Data_Bin!B:B,D27) -> 8 | G27: =F27/SUM($F$25:$F$31) -> 0.16 | H27: =E27-F27 -> 10 | I27: =H27/SUM($H$25:$H$31) -> 0.019723866 | J27: =LN((G27+0.0000000001)/(I27+0.0000000001)) -> 2.0933444 | K27: =IFERROR(J27*(G27-I27),0) -> 0.29364627
D28: Restructured debt with regular payments for less than 6 months | E28: =COUNTIF(Data_Bin!$B:$B,D28) -> 8 | F28: =SUMIFS(Data_Bin!J:J,Data_Bin!B:B,D28) -> 5 | G28: =F28/SUM($F$25:$F$31) -> 0.1 | H28: =E28-F28 -> 3 | I28: =H28/SUM($H$25:$H$31) -> 0.0059171598 | J28: =LN((G28+0.0000000001)/(I28+0.0000000001)) -> 2.8273136 | K28: =IFERROR(J28*(G28-I28),0) -> 0.26600169
D29: Never restructured debt | E29: =COUNTIF(Data_Bin!$B:$B,D29) -> 271 | F29: =SUMIFS(Data_Bin!J:J,Data_Bin!B:B,D29) -> 21 | G29: =F29/SUM($F$25:$F$31) -> 0.42 | H29: =E29-F29 -> 250 | I29: =H29/SUM($H$25:$H$31) -> 0.49309665 | J29: =LN((G29+0.0000000001)/(I29+0.0000000001)) -> -0.16045048 | K29: =IFERROR(J29*(G29-I29),0) -> 0.011728392
D30: Restructured debt in the past | E30: =COUNTIF(Data_Bin!$B:$B,D30) -> 10 | F30: =SUMIFS(Data_Bin!J:J,Data_Bin!B:B,D30) -> 0 | G30: =F30/SUM($F$25:$F$31) -> 0 | H30: =E30-F30 -> 10 | I30: =H30/SUM($H$25:$H$31) -> 0.019723866 | J30: =LN((G30+0.0000000001)/(I30+0.0000000001)) -> -19.099925 | K30: =IFERROR(J30*(G30-I30),0) -> 0.37672436
D31: Credit bureau check not performed | E31: =COUNTIF(Data_Bin!$B:$B,D31) -> 1 | F31: =SUMIFS(Data_Bin!J:J,Data_Bin!B:B,D31) -> 0 | G31: =F31/SUM($F$25:$F$31) -> 0 | H31: =E31-F31 -> 1 | I31: =H31/SUM($H$25:$H$31) -> 0.0019723866 | J31: =LN((G31+0.0000000001)/(I31+0.0000000001)) -> -16.79734 | K31: =IFERROR(J31*(G31-I31),0) -> 0.033130848
D32: Sum | E32: =SUM(E25:E31) -> 557 | F32: =SUM(F25:F31) -> 50 | G32: =SUM(G25:G31) -> 1 | H32: =SUM(H25:H31) -> 507 | I32: =SUM(I25:I31) -> 1 | K32: =SUM(K25:K31) -> 1.1667415
D34: Similarly, a full IV index have been calculated using python (please refer working file)
C53: Suggestion | D53: C3_Worst credit bureau delinquency record in the past 2 years have been underweighted
D54: Bin 'Overdue more than 90 days more than 1 year ago' have 100% of default (7 samples) while 'Record found in credit bureau but no delinquency history' only have 5%
D55: Based on the IV calculation, this shoubd be the strongest predictor and the weight should be closer to 40%
D57: Similarly, F1_Net Fixed Asset is also a strong predictor. Smaller firms (NFA < 150 M) have higher rate of default (~12%) while bigger firms have lower rate of default (~2%)
D59: F3_Sale Growths(%) is massively overweighted. Default rates are flat across all bins (7-13%), no monotone relationship, hence this feature should be dropped or minimized.
D61: C2_Debt rescheduling history is also overweitght. It has less classifying power than C1, and nearly half of data is NA
B63: Question 2
C64: Approach 1 | D64: We will assess the rate of default in each bin of each feature to determine if the current linear method scoring in the scorecard is suitable
D65: Feature | E65: Debt rescheduling history (reschedule) | F65: Only select one option
D67: Bin | E67: Default Count. | F67: Total Count. | G67: Default Rate % | H67: Expert Scorecard score
D68: No debt rescheduling history (payment term relief) | E68: 9 | F68: 185 | G68: 4.86 | H68: 0
D69: Not available | E69: 21 | F69: 282 | G69: 7.45 | H69: 0
D70: Rescheduled debt with regular payments for 6-12 months | E70: 12 | F70: 27 | G70: 44.44 | H70: -100
D71: Rescheduled debt with regular payments for less than 6 months | E71: 4 | F71: 30 | G71: 13.33 | H71: -100
D72: Rescheduled debt with regular payments for more than 12 months | E72: 4 | F72: 33 | G72: 12.12 | H72: -50
...

Sheet Default Rate By bin
A1: Feature | B1: Bin | C1: Default Count | D1: Total Count | E1: Default Rate | F1: Scorecard score
A2: Debt restructuring history | B2: No debt restructuring history | C2: {=SUMPRODUCT((INDEX(Data_Bin_clean!$B$2:$J$558,0,MATCH(A2,Data_Bin_clean!$B$1:$J$1,0))=B2)*(Data_Bin_clean!$J$2:$J$558=1))} -> 12 | D2: {=SUMPRODUCT((INDEX(Data_Bin_clean!$B$2:$J$558,0,MATCH(A2,Data_Bin_clean!$B$1:$J$1,0))=B2)*1)} -> 233 | E2: =IFERROR(ROUND(C2/D2*100,2),0) -> 5.15 | F2: {=_xlfn.XLOOKUP(A2&"|"&B2,Scorecard!$C$2:$C$67&"|"&Scorecard!$D$2:$D$67,Scorecard!$E$2:$E$67,0)} -> 0
A3: Debt restructuring history | B3: Restructured debt with regular payments for more than 12 months | C3: {=SUMPRODUCT((INDEX(Data_Bin_clean!$B$2:$J$558,0,MATCH(A3,Data_Bin_clean!$B$1:$J$1,0))=B3)*(Data_Bin_clean!$J$2:$J$558=1))} -> 4 | D3: {=SUMPRODUCT((INDEX(Data_Bin_clean!$B$2:$J$558,0,MATCH(A3,Data_Bin_clean!$B$1:$J$1,0))=B3)*1)} -> 16 | E3: =IFERROR(ROUND(C3/D3*100,2),0) -> 25 | F3: {=_xlfn.XLOOKUP(A3&"|"&B3,Scorecard!$C$2:$C$67&"|"&Scorecard!$D$2:$D$67,Scorecard!$E$2:$E$67,0)} -> -50
A4: Debt restructuring history | B4: Restructured debt with regular payments for 6-12 months | C4: {=SUMPRODUCT((INDEX(Data_Bin_clean!$B$2:$J$558,0,MATCH(A4,Data_Bin_clean!$B$1:$J$1,0))=B4)*(Data_Bin_clean!$J$2:$J$558=1))} -> 8 | D4: {=SUMPRODUCT((INDEX(Data_Bin_clean!$B$2:$J$558,0,MATCH(A4,Data_Bin_clean!$B$1:$J$1,0))=B4)*1)} -> 18 | E4: =IFERROR(ROUND(C4/D4*100,2),0) -> 44.44 | F4: {=_xlfn.XLOOKUP(A4&"|"&B4,Scorecard!$C$2:$C$67&"|"&Scorecard!$D$2:$D$67,Scorecard!$E$2:$E$67,0)} -> -100
A5: Debt restructuring history | B5: Restructured debt with regular payments for less than 6 months | C5: {=SUMPRODUCT((INDEX(Data_Bin_clean!$B$2:$J$558,0,MATCH(A5,Data_Bin_clean!$B$1:$J$1,0))=B5)*(Data_Bin_clean!$J$2:$J$558=1))} -> 5 | D5: {=SUMPRODUCT((INDEX(Data_Bin_clean!$B$2:$J$558,0,MATCH(A5,Data_Bin_clean!$B$1:$J$1,0))=B5)*1)} -> 8 | E5: =IFERROR(ROUND(C5/D5*100,2),0) -> 62.5 | F5: {=_xlfn.XLOOKUP(A5&"|"&B5,Scorecard!$C$2:$C$67&"|"&Scorecard!$D$2:$D$67,Scorecard!$E$2:$E$67,0)} -> -100
A6: Debt restructuring history | B6: Never restructured debt | C6: {=SUMPRODUCT((INDEX(Data_Bin_clean!$B$2:$J$558,0,MATCH(A6,Data_Bin_clean!$B$1:$J$1,0))=B6)*(Data_Bin_clean!$J$2:$J$558=1))} -> 21 | D6: {=SUMPRODUCT((INDEX(Data_Bin_clean!$B$2:$J$558,0,MATCH(A6,Data_Bin_clean!$B$1:$J$1,0))=B6)*1)} -> 271 | E6: =IFERROR(ROUND(C6/D6*100,2),0) -> 7.75 | F6: {=_xlfn.XLOOKUP(A6&"|"&B6,Scorecard!$C$2:$C$67&"|"&Scorecard!$D$2:$D$67,Scorecard!$E$2:$E$67,0)} -> 0
A7: Debt restructuring history | B7: Restructured debt in the past | C7: {=SUMPRODUCT((INDEX(Data_Bin_clean!$B$2:$J$558,0,MATCH(A7,Data_Bin_clean!$B$1:$J$1,0))=B7)*(Data_Bin_clean!$J$2:$J$558=1))} -> 0 | D7: {=SUMPRODUCT((INDEX(Data_Bin_clean!$B$2:$J$558,0,MATCH(A7,Data_Bin_clean!$B$1:$J$1,0))=B7)*1)} -> 10 | E7: =IFERROR(ROUND(C7/D7*100,2),0) -> 0 | F7: {=_xlfn.XLOOKUP(A7&"|"&B7,Scorecard!$C$2:$C$67&"|"&Scorecard!$D$2:$D$67,Scorecard!$E$2:$E$67,0)} -> -50
A8: Debt restructuring history | B8: Credit bureau check not performed | C8: {=SUMPRODUCT((INDEX(Data_Bin_clean!$B$2:$J$558,0,MATCH(A8,Data_Bin_clean!$B$1:$J$1,0))=B8)*(Data_Bin_clean!$J$2:$J$558=1))} -> 0 | D8: {=SUMPRODUCT((INDEX(Data_Bin_clean!$B$2:$J$558,0,MATCH(A8,Data_Bin_clean!$B$1:$J$1,0))=B8)*1)} -> 1 | E8: =IFERROR(ROUND(C8/D8*100,2),0) -> 0 | F8: {=_xlfn.XLOOKUP(A8&"|"&B8,Scorecard!$C$2:$C$67&"|"&Scorecard!$D$2:$D$67,Scorecard!$E$2:$E$67,0)} -> 0
A9: Debt restructuring history | B9: Not available | C9: {=SUMPRODUCT((INDEX(Data_Bin_clean!$B$2:$J$558,0,MATCH(A9,Data_Bin_clean!$B$1:$J$1,0))=B9)*(Data_Bin_clean!$J$2:$J$558=1))} -> 0 | D9: {=SUMPRODUCT((INDEX(Data_Bin_clean!$B$2:$J$558,0,MATCH(A9,Data_Bin_clean!$B$1:$J$1,0))=B9)*1)} -> 0 | E9: =IFERROR(ROUND(C9/D9*100,2),0) -> 0 | F9: {=_xlfn.XLOOKUP(A9&"|"&B9,Scorecard!$C$2:$C$67&"|"&Scorecard!$D$2:$D$67,Scorecard!$E$2:$E$67,0)} -> 0
A10: Debt rescheduling history (reschedule) | B10: No debt rescheduling history (payment term relief) | C10: {=SUMPRODUCT((INDEX(Data_Bin_clean!$B$2:$J$558,0,MATCH(A10,Data_Bin_clean!$B$1:$J$1,0))=B10)*(Data_Bin_clean!$J$2:$J$558=1))} -> 9 | D10: {=SUMPRODUCT((INDEX(Data_Bin_clean!$B$2:$J$558,0,MATCH(A10,Data_Bin_clean!$B$1:$J$1,0))=B10)*1)} -> 185 | E10: =IFERROR(ROUND(C10/D10*100,2),0) -> 4.86 | F10: {=_xlfn.XLOOKUP(A10&"|"&B10,Scorecard!$C$2:$C$67&"|"&Scorecard!$D$2:$D$67,Scorecard!$E$2:$E$67,0)} -> 0
A11: Debt rescheduling history (reschedule) | B11: Rescheduled debt with regular payments for more than 12 months | C11: {=SUMPRODUCT((INDEX(Data_Bin_clean!$B$2:$J$558,0,MATCH(A11,Data_Bin_clean!$B$1:$J$1,0))=B11)*(Data_Bin_clean!$J$2:$J$558=1))} -> 4 | D11: {=SUMPRODUCT((INDEX(Data_Bin_clean!$B$2:$J$558,0,MATCH(A11,Data_Bin_clean!$B$1:$J$1,0))=B11)*1)} -> 33 | E11: =IFERROR(ROUND(C11/D11*100,2),0) -> 12.12 | F11: {=_xlfn.XLOOKUP(A11&"|"&B11,Scorecard!$C$2:$C$67&"|"&Scorecard!$D$2:$D$67,Scorecard!$E$2:$E$67,0)} -> -50
A12: Debt rescheduling history (reschedule) | B12: Rescheduled debt with regular payments for 6-12 months | C12: {=SUMPRODUCT((INDEX(Data_Bin_clean!$B$2:$J$558,0,MATCH(A12,Data_Bin_clean!$B$1:$J$1,0))=B12)*(Data_Bin_clean!$J$2:$J$558=1))} -> 12 | D12: {=SUMPRODUCT((INDEX(Data_Bin_clean!$B$2:$J$558,0,MATCH(A12,Data_Bin_clean!$B$1:$J$1,0))=B12)*1)} -> 27 | E12: =IFERROR(ROUND(C12/D12*100,2),0) -> 44.44 | F12: {=_xlfn.XLOOKUP(A12&"|"&B12,Scorecard!$C$2:$C$67&"|"&Scorecard!$D$2:$D$67,Scorecard!$E$2:$E$67,0)} -> -100
A13: Debt rescheduling history (reschedule) | B13: Rescheduled debt with regular payments for less than 6 months | C13: {=SUMPRODUCT((INDEX(Data_Bin_clean!$B$2:$J$558,0,MATCH(A13,Data_Bin_clean!$B$1:$J$1,0))=B13)*(Data_Bin_clean!$J$2:$J$558=1))} -> 4 | D13: {=SUMPRODUCT((INDEX(Data_Bin_clean!$B$2:$J$558,0,MATCH(A13,Data_Bin_clean!$B$1:$J$1,0))=B13)*1)} -> 30 | E13: =IFERROR(ROUND(C13/D13*100,2),0) -> 13.33 | F13: {=_xlfn.XLOOKUP(A13&"|"&B13,Scorecard!$C$2:$C$67&"|"&Scorecard!$D$2:$D$67,Scorecard!$E$2:$E$67,0)} -> -100
... A60: Debt Service Coverage Area | B60: Not available | C60: {=SUMPRODUCT((INDEX(Data_Bin_clean!$B$2:$J$558,0,MATCH(A60,Data_Bin_clean!$B$1:$J$1,0))=B60)*(Data_Bin_clean!$J$2:$J$558=1))} -> 18 | D60: {=SUMPRODUCT((INDEX(Data_Bin_clean!$B$2:$J$558,0,MATCH(A60,Data_Bin_clean!$B$1:$J$1,0))=B60)*1)} -> 122 | E60: =IFERROR(ROUND(C60/D60*100,2),0) -> 14.75 | F60: {=_xlfn.XLOOKUP(A60&"|"&B60,Scorecard!$C$2:$C$67&"|"&Scorecard!$D$2:$D$67,Scorecard!$E$2:$E$67,0)} -> 0
A61: Debt Service Coverage Area | B61: >2 | C61: 3 | D61: {=SUMPRODUCT((INDEX(Data_Bin_clean!$B$2:$J$558,0,MATCH(A61,Data_Bin_clean!$B$1:$J$1,0))=B61)*1)} -> 41 | E61: =IFERROR(ROUND(C61/D61*100,2),0) -> 7.32 | F61: {=_xlfn.XLOOKUP(A61&"|"&B61,Scorecard!$C$2:$C$67&"|"&Scorecard!$D$2:$D$67,Scorecard!$E$2:$E$67,0)} -> 100
A62: Debt Service Coverage Area | B62: (1, 1.2) | C62: 3 | D62: {=SUMPRODUCT((INDEX(Data_Bin_clean!$B$2:$J$558,0,MATCH(A62,Data_Bin_clean!$B$1:$J$1,0))=B62)*1)} -> 28 | E62: =IFERROR(ROUND(C62/D62*100,2),0) -> 10.71 | F62: {=_xlfn.XLOOKUP(A62&"|"&B62,Scorecard!$C$2:$C$67&"|"&Scorecard!$D$2:$D$67,Scorecard!$E$2:$E$67,0)} -> 70
